<sdf version='1.7'>
  <model name='swarm_carrier_v2'>
    <link name='base_link'>
      <inertial>
        <pose>-0.000265 -4.8e-05 -0.12408 0 -0 0</pose>
        <mass>15.007</mass>
        <inertia>
          <ixx>0.79653</ixx>
          <ixy>9.3966e-08</ixy>
          <ixz>-2.6473e-07</ixz>
          <iyy>0.69508</iyy>
          <iyz>-5.4034e-08</iyz>
          <izz>1.4565</izz>
        </inertia>
      </inertial>
      <collision name='base_link_collision'>
        <pose>0 0 0 0 -0 0</pose>
        <geometry>
          <mesh>
            <scale>1 1 1</scale>
            <uri>model://swarm_carrier_v2/meshes/base_link_col.STL</uri>
          </mesh>
        </geometry>
        <surface>
          <contact>
            <ode>
              <max_vel>100.0</max_vel>
              <min_depth>0.001</min_depth>
            </ode>
          </contact>
          <friction>
            <ode>
              <mu>100000.0</mu>
              <mu2>100000.0</mu2>
            </ode>
          </friction>
        </surface>
      </collision>
      <visual name='base_link_visual'>
        <pose>0 0 0 0 -0 0</pose>
        <geometry>
          <mesh>
            <scale>1 1 1</scale>
            <uri>model://swarm_carrier_v2/meshes/base_link.STL</uri>
          </mesh>
        </geometry>
      </visual>
    </link>
    <joint name='prop_10_joint' type='revolute'>
      <pose relative_to='base_link'>0 0.87065 0.031899 0 -0 2.5142</pose>
      <parent>base_link</parent>
      <child>prop_10</child>
      <axis>
        <xyz>0 0 1</xyz>
        <limit>
          <lower>-1e+16</lower>
          <upper>1e+16</upper>
          <effort>100</effort>
          <velocity>100</velocity>
        </limit>
        <dynamics>
          <damping>0.004</damping>
          <friction>0</friction>
          <spring_reference>0</spring_reference>
          <spring_stiffness>0</spring_stiffness>
        </dynamics>
      </axis>
    </joint>
    <link name='prop_10'>
      <pose relative_to='prop_10_joint'>0 0 0 0 -0 0</pose>
      <inertial>
        <pose>-0.51098 0.70497 -0.10275 0 -0 0</pose>
        <mass>0.24923</mass>
        <inertia>
          <ixx>14.896</ixx>
          <ixy>0.0069251</ixy>
          <ixz>0.00024738</ixz>
          <iyy>14.926</iyy>
          <iyz>0.00010383</iyz>
          <izz>28.858</izz>
        </inertia>
      </inertial>
      <collision name='prop_10_collision'>
        <pose>0 0 0 0 -0 0</pose>
        <geometry>
          <mesh>
            <scale>1 1 1</scale>
            <uri>model://swarm_carrier_v2/meshes/prop_10_col.STL</uri>
          </mesh>
        </geometry>
      </collision>
      <visual name='prop_10_visual'>
        <pose>0 0 0 0 -0 0</pose>
        <geometry>
          <mesh>
            <scale>1 1 1</scale>
            <uri>model://swarm_carrier_v2/meshes/prop_10.STL</uri>
          </mesh>
        </geometry>
      </visual>
    </link>
    <joint name='prop_1_joint' type='revolute'>
      <pose relative_to='base_link'>1.7088 0 0.031899 0 -0 0.53812</pose>
      <parent>base_link</parent>
      <child>prop_1</child>
      <axis>
        <xyz>0 0 1</xyz>
        <limit>
          <lower>-1e+16</lower>
          <upper>1e+16</upper>
          <effort>100</effort>
          <velocity>100</velocity>
        </limit>
        <dynamics>
          <damping>0.004</damping>
          <friction>0</friction>
          <spring_reference>0</spring_reference>
          <spring_stiffness>0</spring_stiffness>
        </dynamics>
      </axis>
    </joint>
    <link name='prop_1'>
      <pose relative_to='prop_1_joint'>0 0 0 0 -0 0</pose>
      <inertial>
        <pose>0 -5e-06 0.002884 0 -0 0</pose>
        <mass>0.24923</mass>
        <inertia>
          <ixx>0.0072919</ixx>
          <ixy>0.00019978</ixy>
          <ixz>-1.1958e-11</ixz>
          <iyy>6.0017e-05</iyy>
          <iyz>1.5169e-09</iyz>
          <izz>0.0073408</izz>
        </inertia>
      </inertial>
      <collision name='prop_1_collision'>
        <pose>0 0 0 0 -0 0</pose>
        <geometry>
          <mesh>
            <scale>1 1 1</scale>
            <uri>model://swarm_carrier_v2/meshes/prop_1_col.STL</uri>
          </mesh>
        </geometry>
      </collision>
      <visual name='prop_1_visual'>
        <pose>0 0 0 0 -0 0</pose>
        <geometry>
          <mesh>
            <scale>1 1 1</scale>
            <uri>model://swarm_carrier_v2/meshes/prop_1.STL</uri>
          </mesh>
        </geometry>
      </visual>
    </link>
    <joint name='prop_2_joint' type='revolute'>
      <pose relative_to='base_link'>-1.7088 0 0.031899 0 -0 1.1627</pose>
      <parent>base_link</parent>
      <child>prop_2</child>
      <axis>
        <xyz>0 0 1</xyz>
        <limit>
          <lower>-1e+16</lower>
          <upper>1e+16</upper>
          <effort>100</effort>
          <velocity>100</velocity>
        </limit>
        <dynamics>
          <damping>0.004</damping>
          <friction>0</friction>
          <spring_reference>0</spring_reference>
          <spring_stiffness>0</spring_stiffness>
        </dynamics>
      </axis>
    </joint>
    <link name='prop_2'>
      <pose relative_to='prop_2_joint'>0 0 0 0 -0 0</pose>
      <inertial>
        <pose>0 -5e-06 0.002884 0 -0 0</pose>
        <mass>0.24923</mass>
        <inertia>
          <ixx>0.0072919</ixx>
          <ixy>0.00019978</ixy>
          <ixz>1.0345e-11</ixz>
          <iyy>6.0018e-05</iyy>
          <iyz>1.4659e-09</iyz>
          <izz>0.0073408</izz>
        </inertia>
      </inertial>
      <collision name='prop_2_collision'>
        <pose>0 0 0 0 -0 0</pose>
        <geometry>
          <mesh>
            <scale>1 1 1</scale>
            <uri>model://swarm_carrier_v2/meshes/prop_2_col.STL</uri>
          </mesh>
        </geometry>
      </collision>
      <visual name='prop_2_visual'>
        <pose>0 0 0 0 -0 0</pose>
        <geometry>
          <mesh>
            <scale>1 1 1</scale>
            <uri>model://swarm_carrier_v2/meshes/prop_2.STL</uri>
          </mesh>
        </geometry>
      </visual>
    </link>
    <joint name='prop_3_joint' type='revolute'>
      <pose relative_to='base_link'>0.87065 -0.87065 0.031899 0 0 -3.0451</pose>
      <parent>base_link</parent>
      <child>prop_3</child>
      <axis>
        <xyz>0 0 1</xyz>
        <limit>
          <lower>-1e+16</lower>
          <upper>1e+16</upper>
          <effort>100</effort>
          <velocity>100</velocity>
        </limit>
        <dynamics>
          <damping>0.004</damping>
          <friction>0</friction>
          <spring_reference>0</spring_reference>
          <spring_stiffness>0</spring_stiffness>
        </dynamics>
      </axis>
    </joint>
    <link name='prop_3'>
      <pose relative_to='prop_3_joint'>0 0 0 0 -0 0</pose>
      <inertial>
        <pose>-0 -2e-06 0.002884 0 -0 0</pose>
        <mass>0.24924</mass>
        <inertia>
          <ixx>0.0072919</ixx>
          <ixy>-0.00019976</ixy>
          <ixz>-7.4492e-11</ixz>
          <iyy>6.0015e-05</iyy>
          <iyz>-6.1128e-10</iyz>
          <izz>0.0073409</izz>
        </inertia>
      </inertial>
      <collision name='prop_3_collision'>
        <pose>0 0 0 0 -0 0</pose>
        <geometry>
          <mesh>
            <scale>1 1 1</scale>
            <uri>model://swarm_carrier_v2/meshes/prop_3_col.STL</uri>
          </mesh>
        </geometry>
      </collision>
      <visual name='prop_3_visual'>
        <pose>0 0 0 0 -0 0</pose>
        <geometry>
          <mesh>
            <scale>1 1 1</scale>
            <uri>model://swarm_carrier_v2/meshes/prop_3.STL</uri>
          </mesh>
        </geometry>
      </visual>
    </link>
    <joint name='prop_4_joint' type='revolute'>
      <pose relative_to='base_link'>-0.87065 -0.87065 0.031899 0 0 -2.4981</pose>
      <parent>base_link</parent>
      <child>prop_4</child>
      <axis>
        <xyz>0 0 1</xyz>
        <limit>
          <lower>-1e+16</lower>
          <upper>1e+16</upper>
          <effort>100</effort>
          <velocity>100</velocity>
        </limit>
        <dynamics>
          <damping>0.004</damping>
          <friction>0</friction>
          <spring_reference>0</spring_reference>
          <spring_stiffness>0</spring_stiffness>
        </dynamics>
      </axis>
    </joint>
    <link name='prop_4'>
      <pose relative_to='prop_4_joint'>0 0 0 0 -0 0</pose>
      <inertial>
        <pose>-1.2187 -0.17421 -0.10275 0 -0 0</pose>
        <mass>21.379</mass>
        <inertia>
          <ixx>14.927</ixx>
          <ixy>0.0026372</ixy>
          <ixz>0.00017228</ixz>
          <iyy>14.895</iyy>
          <iyz>-0.00020566</iyz>
          <izz>28.858</izz>
        </inertia>
      </inertial>
      <collision name='prop_4_collision'>
        <pose>0 0 0 0 -0 0</pose>
        <geometry>
          <mesh>
            <scale>1 1 1</scale>
            <uri>model://swarm_carrier_v2/meshes/prop_4_col.STL</uri>
          </mesh>
        </geometry>
      </collision>
      <visual name='prop_4_visual'>
        <pose>0 0 0 0 -0 0</pose>
        <geometry>
          <mesh>
            <scale>1 1 1</scale>
            <uri>model://swarm_carrier_v2/meshes/prop_4.STL</uri>
          </mesh>
        </geometry>
      </visual>
    </link>
    <joint name='prop_5_joint' type='revolute'>
      <pose relative_to='base_link'>0.87065 0.87065 0.031899 0 0 -2.952</pose>
      <parent>base_link</parent>
      <child>prop_5</child>
      <axis>
        <xyz>0 0 1</xyz>
        <limit>
          <lower>-1e+16</lower>
          <upper>1e+16</upper>
          <effort>100</effort>
          <velocity>100</velocity>
        </limit>
        <dynamics>
          <damping>0.004</damping>
          <friction>0</friction>
          <spring_reference>0</spring_reference>
          <spring_stiffness>0</spring_stiffness>
        </dynamics>
      </axis>
    </joint>
    <link name='prop_5'>
      <pose relative_to='prop_5_joint'>0 0 0 0 -0 0</pose>
      <inertial>
        <pose>-0 0 0.002884 0 -0 0</pose>
        <mass>0.24923</mass>
        <inertia>
          <ixx>0.0072919</ixx>
          <ixy>-0.00019976</ixy>
          <ixz>1.3989e-11</ixz>
          <iyy>6.0014e-05</iyy>
          <iyz>-6.0697e-11</iyz>
          <izz>0.0073408</izz>
        </inertia>
      </inertial>
      <collision name='prop_5_collision'>
        <pose>0 0 0 0 -0 0</pose>
        <geometry>
          <mesh>
            <scale>1 1 1</scale>
            <uri>model://swarm_carrier_v2/meshes/prop_5_col.STL</uri>
          </mesh>
        </geometry>
      </collision>
      <visual name='prop_5_visual'>
        <pose>0 0 0 0 -0 0</pose>
        <geometry>
          <mesh>
            <scale>1 1 1</scale>
            <uri>model://swarm_carrier_v2/meshes/prop_5.STL</uri>
          </mesh>
        </geometry>
      </visual>
    </link>
    <joint name='prop_6_joint' type='revolute'>
      <pose relative_to='base_link'>-0.87065 0.87065 0.031899 0 0 -2.7347</pose>
      <parent>base_link</parent>
      <child>prop_6</child>
      <axis>
        <xyz>0 0 1</xyz>
        <limit>
          <lower>-1e+16</lower>
          <upper>1e+16</upper>
          <effort>100</effort>
          <velocity>100</velocity>
        </limit>
        <dynamics>
          <damping>0.004</damping>
          <friction>0</friction>
          <spring_reference>0</spring_reference>
          <spring_stiffness>0</spring_stiffness>
        </dynamics>
      </axis>
    </joint>
    <link name='prop_6'>
      <pose relative_to='prop_6_joint'>0 0 0 0 -0 0</pose>
      <inertial>
        <pose>-0 0 0.002884 0 -0 0</pose>
        <mass>0.24923</mass>
        <inertia>
          <ixx>0.0072919</ixx>
          <ixy>-0.00019976</ixy>
          <ixz>1.4081e-11</ixz>
          <iyy>6.0014e-05</iyy>
          <iyz>-5.8528e-11</iyz>
          <izz>0.0073408</izz>
        </inertia>
      </inertial>
      <collision name='prop_6_collision'>
        <pose>0 0 0 0 -0 0</pose>
        <geometry>
          <mesh>
            <scale>1 1 1</scale>
            <uri>model://swarm_carrier_v2/meshes/prop_6_col.STL</uri>
          </mesh>
        </geometry>
      </collision>
      <visual name='prop_6_visual'>
        <pose>0 0 0 0 -0 0</pose>
        <geometry>
          <mesh>
            <scale>1 1 1</scale>
            <uri>model://swarm_carrier_v2/meshes/prop_6.STL</uri>
          </mesh>
        </geometry>
      </visual>
    </link>
    <joint name='prop_7_joint' type='revolute'>
      <pose relative_to='base_link'>0 1.7088 0.031899 0 -0 0.059525</pose>
      <parent>base_link</parent>
      <child>prop_7</child>
      <axis>
        <xyz>0 0 1</xyz>
        <limit>
          <lower>-1e+16</lower>
          <upper>1e+16</upper>
          <effort>100</effort>
          <velocity>100</velocity>
        </limit>
        <dynamics>
          <damping>0.004</damping>
          <friction>0</friction>
          <spring_reference>0</spring_reference>
          <spring_stiffness>0</spring_stiffness>
        </dynamics>
      </axis>
    </joint>
    <link name='prop_7'>
      <pose relative_to='prop_7_joint'>0 0 0 0 -0 0</pose>
      <inertial>
        <pose>5e-06 0 0.002884 0 -0 0</pose>
        <mass>0.24923</mass>
        <inertia>
          <ixx>6.0017e-05</ixx>
          <ixy>-0.00019978</ixy>
          <ixz>-1.6413e-09</ixz>
          <iyy>0.0072919</iyy>
          <iyz>-1.3553e-12</iyz>
          <izz>0.0073408</izz>
        </inertia>
      </inertial>
      <collision name='prop_7_collision'>
        <pose>0 0 0 0 -0 0</pose>
        <geometry>
          <mesh>
            <scale>1 1 1</scale>
            <uri>model://swarm_carrier_v2/meshes/prop_7_col.STL</uri>
          </mesh>
        </geometry>
      </collision>
      <visual name='prop_7_visual'>
        <pose>0 0 0 0 -0 0</pose>
        <geometry>
          <mesh>
            <scale>1 1 1</scale>
            <uri>model://swarm_carrier_v2/meshes/prop_7.STL</uri>
          </mesh>
        </geometry>
      </visual>
    </link>
    <joint name='prop_8_joint' type='revolute'>
      <pose relative_to='base_link'>0 -1.7088 0.031899 0 -0 0.92604</pose>
      <parent>base_link</parent>
      <child>prop_8</child>
      <axis>
        <xyz>0 0 1</xyz>
        <limit>
          <lower>-1e+16</lower>
          <upper>1e+16</upper>
          <effort>100</effort>
          <velocity>100</velocity>
        </limit>
        <dynamics>
          <damping>0.004</damping>
          <friction>0</friction>
          <spring_reference>0</spring_reference>
          <spring_stiffness>0</spring_stiffness>
        </dynamics>
      </axis>
    </joint>
    <link name='prop_8'>
      <pose relative_to='prop_8_joint'>0 0 0 0 -0 0</pose>
      <inertial>
        <pose>-0 -2e-06 0.002884 0 -0 0</pose>
        <mass>0.24923</mass>
        <inertia>
          <ixx>0.0072919</ixx>
          <ixy>0.00019978</ixy>
          <ixz>-1.6201e-10</ixz>
          <iyy>6.0018e-05</iyy>
          <iyz>2.4597e-09</iyz>
          <izz>0.0073408</izz>
        </inertia>
      </inertial>
      <collision name='prop_8_collision'>
        <pose>0 0 0 0 -0 0</pose>
        <geometry>
          <mesh>
            <scale>1 1 1</scale>
            <uri>model://swarm_carrier_v2/meshes/prop_8_col.STL</uri>
          </mesh>
        </geometry>
      </collision>
      <visual name='prop_8_visual'>
        <pose>0 0 0 0 -0 0</pose>
        <geometry>
          <mesh>
            <scale>1 1 1</scale>
            <uri>model://swarm_carrier_v2/meshes/prop_8.STL</uri>
          </mesh>
        </geometry>
      </visual>
    </link>
    <joint name='prop_9_joint' type='revolute'>
      <pose relative_to='base_link'>0 -0.87065 0.031899 0 -0 0.70876</pose>
      <parent>base_link</parent>
      <child>prop_9</child>
      <axis>
        <xyz>0 0 1</xyz>
        <limit>
          <lower>-1e+16</lower>
          <upper>1e+16</upper>
          <effort>100</effort>
          <velocity>100</velocity>
        </limit>
        <dynamics>
          <damping>0.004</damping>
          <friction>0</friction>
          <spring_reference>0</spring_reference>
          <spring_stiffness>0</spring_stiffness>
        </dynamics>
      </axis>
    </joint>
    <link name='prop_9'>
      <pose relative_to='prop_9_joint'>0 0 0 0 -0 0</pose>
      <inertial>
        <pose>0.56653 0.66107 -0.10275 0 -0 0</pose>
        <mass>0.24923</mass>
        <inertia>
          <ixx>14.927</ixx>
          <ixy>0.00051624</ixy>
          <ixz>-0.0001585</ixz>
          <iyy>14.895</iyy>
          <iyz>0.00021646</iyz>
          <izz>28.858</izz>
        </inertia>
      </inertial>
      <collision name='prop_9_collision'>
        <pose>0 0 0 0 -0 0</pose>
        <geometry>
          <mesh>
            <scale>1 1 1</scale>
            <uri>model://swarm_carrier_v2/meshes/prop_9_col.STL</uri>
          </mesh>
        </geometry>
      </collision>
      <visual name='prop_9_visual'>
        <pose>0 0 0 0 -0 0</pose>
        <geometry>
          <mesh>
            <scale>1 1 1</scale>
            <uri>model://swarm_carrier_v2/meshes/prop_9.STL</uri>
          </mesh>
        </geometry>
      </visual>
    </link>
  </model>
</sdf>
