<?xml version="1.0" encoding="utf-8"?>
<!-- This URDF was automatically created by SolidWorks to URDF Exporter! Originally created by Stephen Brawner (brawner@gmail.com) 
     Commit Version: 1.5.1-0-g916b5db  Build Version: 1.5.7152.31018
     For more information, please see http://wiki.ros.org/sw_urdf_exporter -->
<robot
  name="RoverV1.3.SLDASM">
  <link
    name="base_link">
    <inertial>
      <origin
        xyz="-0.011376 0.0026377 -0.050316"
        rpy="0 0 0" />
      <mass
        value="10.704" />
      <inertia
        ixx="0.059189"
        ixy="-1.249E-06"
        ixz="-2.2283E-07"
        iyy="0.1305"
        iyz="-3.4556E-07"
        izz="0.14645" />
    </inertial>
    <visual>
      <origin
        xyz="0 0 0"
        rpy="0 0 0" />
      <geometry>
        <mesh
          filename="package://RoverV1.3.SLDASM/meshes/base_link.STL" />
      </geometry>
      <material
        name="">
        <color
          rgba="0.89804 0.91765 0.92941 1" />
      </material>
    </visual>
    <collision>
      <origin
        xyz="0 0 0"
        rpy="0 0 0" />
      <geometry>
        <mesh
          filename="package://RoverV1.3.SLDASM/meshes/base_link.STL" />
      </geometry>
    </collision>
  </link>
  <link
    name="RL_tire">
    <inertial>
      <origin
        xyz="-7.3908E-08 -0.0036834 -1.4247E-05"
        rpy="0 0 0" />
      <mass
        value="1.3019" />
      <inertia
        ixx="0.0048572"
        ixy="4.444E-09"
        ixz="-2.5979E-09"
        iyy="0.0085234"
        iyz="1.414E-05"
        izz="0.0048572" />
    </inertial>
    <visual>
      <origin
        xyz="0 0 0"
        rpy="0 0 0" />
      <geometry>
        <mesh
          filename="package://RoverV1.3.SLDASM/meshes/RL_tire.STL" />
      </geometry>
      <material
        name="">
        <color
          rgba="0.79216 0.81961 0.93333 1" />
      </material>
    </visual>
    <collision>
      <origin
        xyz="0 0 0"
        rpy="0 0 0" />
      <geometry>
        <mesh
          filename="package://RoverV1.3.SLDASM/meshes/RL_tire.STL" />
      </geometry>
    </collision>
  </link>
  <joint
    name="RL_tire_joint"
    type="revolute">
    <origin
      xyz="-0.23 0.42963 -0.14076"
      rpy="0 0 0" />
    <parent
      link="base_link" />
    <child
      link="RL_tire" />
    <axis
      xyz="0 -0.99999 -0.0038569" />
    <limit
      lower="-1E+19"
      upper="1E+19"
      effort="100"
      velocity="100" />
    <dynamics
      damping="0.004" />
  </joint>
  <link
    name="RR_tire">
    <inertial>
      <origin
        xyz="1.0863E-07 0.0036834 -1.4186E-05"
        rpy="0 0 0" />
      <mass
        value="1.3019" />
      <inertia
        ixx="0.0048572"
        ixy="4.9199E-09"
        ixz="1.2438E-08"
        iyy="0.0085235"
        iyz="-1.4141E-05"
        izz="0.0048573" />
    </inertial>
    <visual>
      <origin
        xyz="0 0 0"
        rpy="0 0 0" />
      <geometry>
        <mesh
          filename="package://RoverV1.3.SLDASM/meshes/RR_tire.STL" />
      </geometry>
      <material
        name="">
        <color
          rgba="0.79216 0.81961 0.93333 1" />
      </material>
    </visual>
    <collision>
      <origin
        xyz="0 0 0"
        rpy="0 0 0" />
      <geometry>
        <mesh
          filename="package://RoverV1.3.SLDASM/meshes/RR_tire.STL" />
      </geometry>
    </collision>
  </link>
  <joint
    name="RR_tire_joint"
    type="revolute">
    <origin
      xyz="-0.23 -0.42963 -0.14076"
      rpy="0 0 0" />
    <parent
      link="base_link" />
    <child
      link="RR_tire" />
    <axis
      xyz="0 0.99999 -0.0038568" />
    <limit
      lower="-1E+19"
      upper="1E+19"
      effort="100"
      velocity="100" />
    <dynamics
      damping="0.004" />
  </joint>
  <link
    name="FR_tire">
    <inertial>
      <origin
        xyz="7.3908E-08 0.0036834 -1.4247E-05"
        rpy="0 0 0" />
      <mass
        value="1.3019" />
      <inertia
        ixx="0.0048572"
        ixy="4.444E-09"
        ixz="2.5979E-09"
        iyy="0.0085234"
        iyz="-1.414E-05"
        izz="0.0048572" />
    </inertial>
    <visual>
      <origin
        xyz="0 0 0"
        rpy="0 0 0" />
      <geometry>
        <mesh
          filename="package://RoverV1.3.SLDASM/meshes/FR_tire.STL" />
      </geometry>
      <material
        name="">
        <color
          rgba="0.79216 0.81961 0.93333 1" />
      </material>
    </visual>
    <collision>
      <origin
        xyz="0 0 0"
        rpy="0 0 0" />
      <geometry>
        <mesh
          filename="package://RoverV1.3.SLDASM/meshes/FR_tire.STL" />
      </geometry>
    </collision>
  </link>
  <joint
    name="FR_tire_joint"
    type="revolute">
    <origin
      xyz="0.23 -0.42963 -0.14076"
      rpy="0 0 0" />
    <parent
      link="base_link" />
    <child
      link="FR_tire" />
    <axis
      xyz="0 0.99999 -0.0038568" />
    <limit
      lower="-1E+19"
      upper="1E+19"
      effort="100"
      velocity="100" />
    <dynamics
      damping="0.004" />
  </joint>
  <link
    name="FL_tire">
    <inertial>
      <origin
        xyz="0 0 0"
        rpy="0 0 0" />
      <mass
        value="0" />
      <inertia
        ixx="0"
        ixy="0"
        ixz="0"
        iyy="0"
        iyz="0"
        izz="0" />
    </inertial>
    <visual>
      <origin
        xyz="0 0 0"
        rpy="0 0 0" />
      <geometry>
        <mesh
          filename="package://RoverV1.3.SLDASM/meshes/FL_tire.STL" />
      </geometry>
      <material
        name="">
        <color
          rgba="1 1 1 1" />
      </material>
    </visual>
    <collision>
      <origin
        xyz="0 0 0"
        rpy="0 0 0" />
      <geometry>
        <mesh
          filename="package://RoverV1.3.SLDASM/meshes/FL_tire.STL" />
      </geometry>
    </collision>
  </link>
  <joint
    name="FL_tire_joint"
    type="revolute">
    <origin
      xyz="0.23 0.42963 -0.14076"
      rpy="0 0 0" />
    <parent
      link="base_link" />
    <child
      link="FL_tire" />
    <axis
      xyz="0 -0.99999 -0.0038569" />
    <limit
      lower="-1E+19"
      upper="1E+19"
      effort="100"
      velocity="100" />
    <dynamics
      damping="0.004" />
  </joint>
</robot>